Workbook
Name WorldWidth: '01_世界设置'!$C$6
Name WorldHeight: '01_世界设置'!$C$7
Name MasterWidthPx: '01_世界设置'!$C$11
Name MasterHeightPx: '01_世界设置'!$C$12
Name PreviewWidthPx: '01_世界设置'!$C$13
Name PreviewHeightPx: '01_世界设置'!$C$14
Name CoordinateDecimals: '01_世界设置'!$C$21
Name dict_map_level: '10_数据字典'!$B$2:$B$8
Name dict_object_type: '10_数据字典'!$B$9:$B$30
Name dict_location_type: '10_数据字典'!$B$31:$B$49
Name dict_path_type: '10_数据字典'!$B$50:$B$63
Name dict_building_type: '10_数据字典'!$B$64:$B$96
Name dict_state_code: '10_数据字典'!$B$97:$B$108
Name dict_review_status: '10_数据字典'!$B$109:$B$115
Name dict_production_status: '10_数据字典'!$B$116:$B$123
Name dict_direction: '10_数据字典'!$B$124:$B$132
Name dict_geometry_type: '10_数据字典'!$B$133:$B$136
Name dict_boolean: '10_数据字典'!$B$137:$B$138
Name dict_display_rule: '10_数据字典'!$B$139:$B$142
Name dict_anchor_rule: '10_数据字典'!$B$143:$B$148
Name dict_passage_status: '10_数据字典'!$B$149:$B$156
Name dict_capacity: '10_数据字典'!$B$157:$B$161
Name dict_file_format: '10_数据字典'!$B$162:$B$170
Name dict_asset_type: '10_数据字典'!$B$171:$B$180
Name dict_check_result: '10_数据字典'!$B$181:$B$185
Name dict_check_type: '10_数据字典'!$B$186:$B$196
Name dict_road_level: '10_数据字典'!$B$197:$B$202
Name dict_build_status: '10_数据字典'!$B$203:$B$208
Name dict_state_category: '10_数据字典'!$B$209:$B$216
Name dict_source_format: '10_数据字典'!$B$217:$B$222
Name dict_export_format: '10_数据字典'!$B$223:$B$226

Sheet 00_使用说明
A1: 02_地图坐标与对象锚点表｜使用说明
A3: 文件用途 | B3: 统一管理世界逻辑坐标、固定地理、地点、路径、LOD、建筑、状态、美术资产和跨层级验收。
A4: 核心地图原则 | B4: 所有地图层级表现的是同一个世界。放大只增加细节，不重新生成另一套城市、道路、河流和建筑布局。
A5: 坐标区别 | B5: 世界逻辑坐标：全世界统一；地图局部坐标：某层/区域内部；图片像素坐标：PSB/PNG画布；建筑院落局部坐标：建筑内部或院落空间。四者不得混用。
A6: 对象ID规则 | B6: 重要对象必须使用唯一稳定ID；PSB、PNG、程序和其他数据文件均通过对象ID关联。投入使用后不得随意改名或重用。
A7: ID格式 | B7: GEO-类型-流水号；LOC-类型-流水号；PATH-类型-流水号；BLD-地点简称-类型-流水号；ASSET-对象ID-状态-LOD；CHK-流水号。示例：GEO-RIV-0001、LOC-CITY-0001、PATH-ROAD-0001、BLD-ZS-SHOP-0001、ASSET-BLD-ZS-SHOP-0001-NORMAL-L04、CHK-0001。
A8: 推荐填写顺序 | B8: 01_世界设置 → 02_固定地理 → 03_地点锚点 → 04_路径网络 → 05_层级表现LOD → 06_建筑锚点 → 08_资产清单 → 09_连续性验收。
A9: 美术与程序关系 | B9: PSB/PNG只提供表现资产；程序、数据和资产以对象ID关联。动态设施、所有权、状态、库存和情报不得永久画死在背景图中。
A10: 严禁事项 | B10: 不得凭肉眼在下一层重新放置城市；不得把世界坐标直接等同图片像素；不得在缩放或进入场景时生成第二套地点、路线或设施。
A11: 常见错误 | B11: 零坐标与空白混淆、ID重复、对象引用不存在、路径起终点相同、坐标越界、最小值大于最大值、LOD改变世界事实、资产文件名重复。
A12: 数据维护责任 | B12: 录入者负责来源和字段完整性；审核者负责坐标、引用、连续性和许可证；程序与美术只消费已审核的稳定对象ID。
A13: 版本信息 | B13: 模板版本 V0.1；生成脚本可重复执行并覆盖同名文件。正式录入后重新生成前必须备份或编写迁移脚本。
A14: 修改记录 | B14: V0.1：建立空白正式模板、系统字典、坐标公式、数据验证、条件格式和校验汇总。

Sheet 01_世界设置
A1: 参数编码 | B1: 参数名称 | C1: 参数值 | D1: 单位 | E1: 是否必填 | F1: 允许修改 | G1: 说明 | I1: 坐标换算示例（输入世界X/Y）
A2: PROJECT_NAME | B2: 项目名称 | C2: 统一世界地图系统 | D2: 文本 | E2: 是 | F2: 是 | G2: 项目显示名称 | I2: 世界X | J2: 世界Y | K2: 母版像素X | L2: 母版像素Y | M2: 预览像素X | N2: 预览像素Y
A3: DOC_VERSION | B3: 文档版本 | C3: V0.1 | D3: 文本 | E3: 是 | F3: 是 | G3: 模板与数据版本 | K3: =IF(OR(I3="",J3=""),"",ROUND(I3/WorldWidth*MasterWidthPx,CoordinateDecimals)) | L3: =IF(OR(I3="",J3=""),"",ROUND(J3/WorldHeight*MasterHeightPx,CoordinateDecimals)) | M3: =IF(OR(I3="",J3=""),"",ROUND(I3/WorldWidth*PreviewWidthPx,CoordinateDecimals)) | N3: =IF(OR(I3="",J3=""),"",ROUND(J3/WorldHeight*PreviewHeightPx,CoordinateDecimals))
A4: GAME_START_YEAR | B4: 游戏起始年份 | D4: 年 | E4: 是 | F4: 是 | G4: 确认历史开局后填写
A5: SOURCE_BASE_DATE | B5: 历史资料基准日期 | D5: 日期 | E5: 是 | F5: 是 | G5: 资料冻结或审核基准日期 | I5: 公式 | J5: 母版像素X = 世界X ÷ 世界逻辑宽度 × 母版画布宽度；Y轴及预览图同理。空白不按0计算。
A6: WORLD_WIDTH | B6: 世界逻辑宽度 | C6: 100000 | D6: 逻辑单位 | E6: 是 | F6: 谨慎 | G6: 世界X有效范围为0至该值
A7: WORLD_HEIGHT | B7: 世界逻辑高度 | C7: 60000 | D7: 逻辑单位 | E7: 是 | F7: 谨慎 | G7: 世界Y有效范围为0至该值
A8: WORLD_ORIGIN | B8: 世界原点 | C8: 左上角 | D8: 文本 | E8: 是 | F8: 否 | G8: 统一坐标原点
A9: X_DIRECTION | B9: X轴方向 | C9: 向右增加 | D9: 文本 | E9: 是 | F9: 否 | G9: 全层级一致
A10: Y_DIRECTION | B10: Y轴方向 | C10: 向下增加 | D10: 文本 | E10: 是 | F10: 否 | G10: 全层级一致
A11: MASTER_WIDTH_PX | B11: 天下母版宽度px | C11: 15360 | D11: px | E11: 是 | F11: 谨慎 | G11: PSB母版画布宽度
A12: MASTER_HEIGHT_PX | B12: 天下母版高度px | C12: 8640 | D12: px | E12: 是 | F12: 谨慎 | G12: PSB母版画布高度
A13: PREVIEW_WIDTH_PX | B13: 预览图宽度px | C13: 3840 | D13: px | E13: 是 | F13: 是 | G13: 预览PNG宽度
A14: PREVIEW_HEIGHT_PX | B14: 预览图高度px | C14: 2160 | D14: px | E14: 是 | F14: 是 | G14: 预览PNG高度
A15: COLOR_MODE | B15: 色彩模式 | C15: RGB | D15: 文本 | E15: 是 | F15: 否 | G15: 美术母版色彩模式
A16: COLOR_DEPTH | B16: 色彩深度 | C16: 16位 | D16: 文本 | E16: 是 | F16: 谨慎 | G16: 美术母版色彩深度
A17: COLOR_SPACE | B17: 色彩空间 | C17: sRGB | D17: 文本 | E17: 是 | F17: 谨慎 | G17: 统一色彩空间
A18: LIGHT_DIRECTION | B18: 默认光照方向 | C18: 左上至右下 | D18: 文本 | E18: 是 | F18: 是 | G18: 地图和资产统一光照
A19: MASTER_FORMAT | B19: 主母版格式 | C19: PSB | D19: 文本 | E19: 是 | F19: 否 | G19: 主母版文件格式
A20: DYNAMIC_FORMAT | B20: 动态对象格式 | C20: PNG | D20: 文本 | E20: 是 | F20: 否 | G20: 动态对象导出格式
A21: COORD_DECIMALS | B21: 坐标小数位 | C21: 2 | D21: 位 | E21: 是 | F21: 是 | G21: 坐标显示与交换精度

Sheet 02_固定地理
A1: 对象ID | B1: 中文名称 | C1: 备用名称 | D1: 对象类型 | E1: 父级对象ID | F1: 世界中心X | G1: 世界中心Y | H1: 最小X | I1: 最小Y | J1: 最大X | K1: 最大Y | L1: 几何类型 | M1: 路径或多边形文件 | N1: 最低显示层级 | O1: 最高显示层级 | P1: 是否固定 | Q1: 通行影响 | R1: 水运影响 | S1: 农业影响 | T1: 军事影响 | U1: 美术资产ID | V1: 资料来源 | W1: 资料版本 | X1: 审核状态 | Y1: 备注

Sheet 03_地点锚点
A1: 地点ID | B1: 中文名称 | C1: 备用名称 | D1: 地点类型 | E1: 父级行政对象ID | F1: 父级地点ID | G1: 世界X | H1: 世界Y | I1: 海拔或地形等级 | J1: 朝向 | K1: 最低显示层级 | L1: 最高显示层级 | M1: 天下图表现 | N1: 州郡图表现 | O1: 县域图表现 | P1: 城镇图表现 | Q1: 固定位置 | R1: 允许迁移 | S1: 当前资产ID | T1: 历史资料来源 | U1: 资料版本 | V1: 审核状态 | W1: 备注

Sheet 04_路径网络
A1: 路径ID | B1: 路径名称 | C1: 路径类型 | D1: 起点对象ID | E1: 终点对象ID | F1: 父级路径ID | G1: 路径文件 | H1: 节点数量 | I1: 道路等级 | J1: 基础宽度 | K1: 基础速度系数 | L1: 容量等级 | M1: 允许军团 | N1: 允许商队 | O1: 允许平民 | P1: 允许车辆 | Q1: 允许船只 | R1: 季节影响 | S1: 天气影响 | T1: 控制对象ID | U1: 建设状态 | V1: 通行状态 | W1: 最低显示层级 | X1: 最高显示层级 | Y1: 资料来源 | Z1: 审核状态 | AA1: 备注

Sheet 05_层级表现LOD
A1: 对象ID | B1: 对象类别 | C1: 天下战略图是否显示 | D1: 天下战略图表现 | E1: 州郡区域图是否显示 | F1: 州郡区域图表现 | G1: 县域乡野图是否显示 | H1: 县域乡野图表现 | I1: 城镇空间图是否显示 | J1: 城镇空间图表现 | K1: 村庄庄园图是否显示 | L1: 村庄庄园图表现 | M1: 建筑院落图是否显示 | N1: 建筑院落图表现 | O1: 战场图是否显示 | P1: 战场图表现 | Q1: 聚合规则 | R1: 替换资产规则 | S1: 标签显示规则 | T1: 情报影响规则 | U1: 备注

Sheet 06_建筑锚点
A1: 建筑ID | B1: 建筑名称 | C1: 建筑类型 | D1: 所属地点ID | E1: 所属街区或村落ID | F1: 世界X | G1: 世界Y | H1: 城镇局部X | I1: 城镇局部Y | J1: 院落局部X | K1: 院落局部Y | L1: 朝向 | M1: 主入口方向 | N1: 主入口锚点X | O1: 主入口锚点Y | P1: 建筑占地宽度 | Q1: 建筑占地高度 | R1: 锚点规则 | S1: 所有权对象ID | T1: 运营状态 | U1: 当前资产ID | V1: 关联室内图ID | W1: 可进入 | X1: 可破坏 | Y1: 可扩建 | Z1: 最低显示层级 | AA1: 资料来源 | AB1: 审核状态 | AC1: 备注

Sheet 07_动态状态
A1: 状态编码 | B1: 状态名称 | C1: 状态类别 | D1: 适用对象类型 | E1: 是否替换主体资产 | F1: 主体资产后缀 | G1: 覆盖层资产后缀 | H1: 是否影响碰撞 | I1: 是否影响通行 | J1: 是否影响功能 | K1: 是否影响人口 | L1: 是否影响库存 | M1: 是否影响所有权 | N1: 进入条件 | O1: 退出条件 | P1: 显示优先级 | Q1: 备注
A2: NORMAL | B2: 正常 | C2: 常态 | D2: 其他 | E2: 否 | H2: 否 | I2: 否 | J2: 否 | K2: 否 | L2: 否 | M2: 否
A3: CLOSED | B3: 关闭 | C3: 运营 | D3: 其他 | E3: 否 | H3: 否 | I3: 否 | J3: 否 | K3: 否 | L3: 否 | M3: 否
A4: BUILDING | B4: 建设中 | C4: 建设 | D4: 其他 | E4: 否 | H4: 否 | I4: 否 | J4: 否 | K4: 否 | L4: 否 | M4: 否
A5: EXPANDED | B5: 扩建 | C5: 建设 | D5: 其他 | E5: 否 | H5: 否 | I5: 否 | J5: 否 | K5: 否 | L5: 否 | M5: 否
A6: DAMAGED | B6: 损坏 | C6: 损毁 | D6: 其他 | E6: 否 | H6: 否 | I6: 否 | J6: 否 | K6: 否 | L6: 否 | M6: 否
A7: BURNING | B7: 火灾 | C7: 灾害 | D7: 其他 | E7: 否 | H7: 否 | I7: 否 | J7: 否 | K7: 否 | L7: 否 | M7: 否
A8: ABANDONED | B8: 废弃 | C8: 运营 | D8: 其他 | E8: 否 | H8: 否 | I8: 否 | J8: 否 | K8: 否 | L8: 否 | M8: 否
A9: OCCUPIED | B9: 被占用 | C9: 占领 | D9: 其他 | E9: 否 | H9: 否 | I9: 否 | J9: 否 | K9: 否 | L9: 否 | M9: 否
A10: BESIEGED | B10: 被围困 | C10: 占领 | D10: 其他 | E10: 否 | H10: 否 | I10: 否 | J10: 否 | K10: 否 | L10: 否 | M10: 否
A11: FLOODED | B11: 被淹 | C11: 灾害 | D11: 其他 | E11: 否 | H11: 否 | I11: 否 | J11: 否 | K11: 否 | L11: 否 | M11: 否
A12: LOOTED | B12: 被劫掠 | C12: 损毁 | D12: 其他 | E12: 否 | H12: 否 | I12: 否 | J12: 否 | K12: 否 | L12: 否 | M12: 否
A13: UNKNOWN | B13: 未知 | C13: 情报 | D13: 其他 | E13: 否 | H13: 否 | I13: 否 | J13: 否 | K13: 否 | L13: 否 | M13: 否

Sheet 08_资产清单
A1: 资产ID | B1: 资产名称 | C1: 对象ID | D1: 资产类别 | E1: 状态编码 | F1: LOD层级 | G1: 文件名 | H1: 源文件路径 | I1: 导出文件路径 | J1: 源文件格式 | K1: 导出格式 | L1: 画布宽度px | M1: 画布高度px | N1: 锚点X | O1: 锚点Y | P1: 阴影是否独立 | Q1: 文字是否独立 | R1: 旗帜是否独立 | S1: 所有权颜色是否独立 | T1: 版本 | U1: 制作人 | V1: 审核人 | W1: 制作状态 | X1: 审核状态 | Y1: 备注

Sheet 09_连续性验收
A1: 验收ID | B1: 对象ID | C1: 检查类型 | D1: 上级地图 | E1: 下级地图 | F1: 上级地图坐标X | G1: 上级地图坐标Y | H1: 下级换算坐标X | I1: 下级换算坐标Y | J1: 坐标偏差 | K1: 允许偏差 | L1: 方向一致 | M1: 连接关系一致 | N1: 外形继承 | O1: 状态继承 | P1: 情报继承 | Q1: 损毁继承 | R1: 检查结果 | S1: 问题说明 | T1: 责任人 | U1: 检查日期 | V1: 复核人 | W1: 复核日期 | X1: 备注
J2: =IF(COUNTA(F2:I2)<4,"",SQRT((F2-H2)^2+(G2-I2)^2))
J3: =IF(COUNTA(F3:I3)<4,"",SQRT((F3-H3)^2+(G3-I3)^2))
J4: =IF(COUNTA(F4:I4)<4,"",SQRT((F4-H4)^2+(G4-I4)^2))
J5: =IF(COUNTA(F5:I5)<4,"",SQRT((F5-H5)^2+(G5-I5)^2))
J6: =IF(COUNTA(F6:I6)<4,"",SQRT((F6-H6)^2+(G6-I6)^2))
J7: =IF(COUNTA(F7:I7)<4,"",SQRT((F7-H7)^2+(G7-I7)^2))
J8: =IF(COUNTA(F8:I8)<4,"",SQRT((F8-H8)^2+(G8-I8)^2))
J9: =IF(COUNTA(F9:I9)<4,"",SQRT((F9-H9)^2+(G9-I9)^2))
J10: =IF(COUNTA(F10:I10)<4,"",SQRT((F10-H10)^2+(G10-I10)^2))
J11: =IF(COUNTA(F11:I11)<4,"",SQRT((F11-H11)^2+(G11-I11)^2))
J12: =IF(COUNTA(F12:I12)<4,"",SQRT((F12-H12)^2+(G12-I12)^2))
J13: =IF(COUNTA(F13:I13)<4,"",SQRT((F13-H13)^2+(G13-I13)^2))
... J501: =IF(COUNTA(F501:I501)<4,"",SQRT((F501-H501)^2+(G501-I501)^2))

Sheet 10_数据字典
A1: 字典分类 | B1: 字典值 | C1: 说明
A2: 地图层级 | B2: L01_天下战略图 | C2: 由本页统一维护；业务表下拉不得硬编码。
A3: 地图层级 | B3: L02_州郡区域图 | C3: 由本页统一维护；业务表下拉不得硬编码。
A4: 地图层级 | B4: L03_县域乡野图 | C4: 由本页统一维护；业务表下拉不得硬编码。
A5: 地图层级 | B5: L04_城镇空间图 | C5: 由本页统一维护；业务表下拉不得硬编码。
A6: 地图层级 | B6: L05_村庄庄园图 | C6: 由本页统一维护；业务表下拉不得硬编码。
A7: 地图层级 | B7: L06_建筑院落图 | C7: 由本页统一维护；业务表下拉不得硬编码。
A8: 地图层级 | B8: L07_战场地图 | C8: 由本页统一维护；业务表下拉不得硬编码。
A9: 对象类型 | B9: 海域 | C9: 由本页统一维护；业务表下拉不得硬编码。
A10: 对象类型 | B10: 海岸线 | C10: 由本页统一维护；业务表下拉不得硬编码。
A11: 对象类型 | B11: 河流 | C11: 由本页统一维护；业务表下拉不得硬编码。
A12: 对象类型 | B12: 湖泊 | C12: 由本页统一维护；业务表下拉不得硬编码。
... A226: 导出格式 | B226: 其他 | C226: 由本页统一维护；业务表下拉不得硬编码。

Sheet 11_校验结果
A1: 问题编号 | B1: 问题级别 | C1: 工作表 | D1: 对象ID | E1: 字段 | F1: 问题说明 | G1: 建议处理 | H1: 校验状态
A2: =IF(F2<>"","ISSUE-"&TEXT(ROW()-1,"00000"),"") | B2: =IF(F2<>"","错误","") | C2: =IF('02_固定地理'!A2<>"","02_固定地理","") | D2: =IF('02_固定地理'!A2<>"",'02_固定地理'!A2,"") | E2: =IF(F2<>"","综合校验","") | F2: =IF('02_固定地理'!A2<>"",IF('02_固定地理'!A2="","缺少对象ID；","")&IF('02_固定地理'!B2="","缺少中文名称；","")&IF('02_固定地理'!D2="","缺少对象类型；","")&IF(AND('02_固定地理'!F2<>"",OR('02_固定地理'!F2<0,'02_固定地理'!F2>WorldWidth)),"世界中心X越界；","")&IF(AND('02_固定地理'!G2<>"",OR('02_固定地理'!G2<0,'02_固定地理'!G2>WorldHeight)),"世界中心Y越界；","")&IF(AND('02_固定地理'!H2<>"",'02_固定地理'!J2<>"",'02_固定地理'!H2>'02_固定地理'!J2),"最小X大于最大X；","")&IF(AND('02_固定地理'!I2<>"",'02_固定地理'!K2<>"",'02_固定地理'!I2>'02_固定地理'!K2),"最小Y大于最大Y；","")&IF(AND('02_固定地理'!E2<>"",COUNTIF('02_固定地理'!$A$2:$A$501,'02_固定地理'!E2)=0),"父级对象不存在；","")&IF(AND('02_固定地理'!A2<>"",COUNTIF('02_固定地理'!$A$2:$A$501,'02_固定地理'!A2)>1),"ID重复；",""),"") | G2: =IF(F2<>"","按字段批注、数据字典和来源记录修正后复核","") | H2: =IF(F2<>"","待处理","")
A3: =IF(F3<>"","ISSUE-"&TEXT(ROW()-1,"00000"),"") | B3: =IF(F3<>"","错误","") | C3: =IF('02_固定地理'!A3<>"","02_固定地理","") | D3: =IF('02_固定地理'!A3<>"",'02_固定地理'!A3,"") | E3: =IF(F3<>"","综合校验","") | F3: =IF('02_固定地理'!A3<>"",IF('02_固定地理'!A3="","缺少对象ID；","")&IF('02_固定地理'!B3="","缺少中文名称；","")&IF('02_固定地理'!D3="","缺少对象类型；","")&IF(AND('02_固定地理'!F3<>"",OR('02_固定地理'!F3<0,'02_固定地理'!F3>WorldWidth)),"世界中心X越界；","")&IF(AND('02_固定地理'!G3<>"",OR('02_固定地理'!G3<0,'02_固定地理'!G3>WorldHeight)),"世界中心Y越界；","")&IF(AND('02_固定地理'!H3<>"",'02_固定地理'!J3<>"",'02_固定地理'!H3>'02_固定地理'!J3),"最小X大于最大X；","")&IF(AND('02_固定地理'!I3<>"",'02_固定地理'!K3<>"",'02_固定地理'!I3>'02_固定地理'!K3),"最小Y大于最大Y；","")&IF(AND('02_固定地理'!E3<>"",COUNTIF('02_固定地理'!$A$2:$A$501,'02_固定地理'!E3)=0),"父级对象不存在；","")&IF(AND('02_固定地理'!A3<>"",COUNTIF('02_固定地理'!$A$2:$A$501,'02_固定地理'!A3)>1),"ID重复；",""),"") | G3: =IF(F3<>"","按字段批注、数据字典和来源记录修正后复核","") | H3: =IF(F3<>"","待处理","")
A4: =IF(F4<>"","ISSUE-"&TEXT(ROW()-1,"00000"),"") | B4: =IF(F4<>"","错误","") | C4: =IF('02_固定地理'!A4<>"","02_固定地理","") | D4: =IF('02_固定地理'!A4<>"",'02_固定地理'!A4,"") | E4: =IF(F4<>"","综合校验","") | F4: =IF('02_固定地理'!A4<>"",IF('02_固定地理'!A4="","缺少对象ID；","")&IF('02_固定地理'!B4="","缺少中文名称；","")&IF('02_固定地理'!D4="","缺少对象类型；","")&IF(AND('02_固定地理'!F4<>"",OR('02_固定地理'!F4<0,'02_固定地理'!F4>WorldWidth)),"世界中心X越界；","")&IF(AND('02_固定地理'!G4<>"",OR('02_固定地理'!G4<0,'02_固定地理'!G4>WorldHeight)),"世界中心Y越界；","")&IF(AND('02_固定地理'!H4<>"",'02_固定地理'!J4<>"",'02_固定地理'!H4>'02_固定地理'!J4),"最小X大于最大X；","")&IF(AND('02_固定地理'!I4<>"",'02_固定地理'!K4<>"",'02_固定地理'!I4>'02_固定地理'!K4),"最小Y大于最大Y；","")&IF(AND('02_固定地理'!E4<>"",COUNTIF('02_固定地理'!$A$2:$A$501,'02_固定地理'!E4)=0),"父级对象不存在；","")&IF(AND('02_固定地理'!A4<>"",COUNTIF('02_固定地理'!$A$2:$A$501,'02_固定地理'!A4)>1),"ID重复；",""),"") | G4: =IF(F4<>"","按字段批注、数据字典和来源记录修正后复核","") | H4: =IF(F4<>"","待处理","")
A5: =IF(F5<>"","ISSUE-"&TEXT(ROW()-1,"00000"),"") | B5: =IF(F5<>"","错误","") | C5: =IF('02_固定地理'!A5<>"","02_固定地理","") | D5: =IF('02_固定地理'!A5<>"",'02_固定地理'!A5,"") | E5: =IF(F5<>"","综合校验","") | F5: =IF('02_固定地理'!A5<>"",IF('02_固定地理'!A5="","缺少对象ID；","")&IF('02_固定地理'!B5="","缺少中文名称；","")&IF('02_固定地理'!D5="","缺少对象类型；","")&IF(AND('02_固定地理'!F5<>"",OR('02_固定地理'!F5<0,'02_固定地理'!F5>WorldWidth)),"世界中心X越界；","")&IF(AND('02_固定地理'!G5<>"",OR('02_固定地理'!G5<0,'02_固定地理'!G5>WorldHeight)),"世界中心Y越界；","")&IF(AND('02_固定地理'!H5<>"",'02_固定地理'!J5<>"",'02_固定地理'!H5>'02_固定地理'!J5),"最小X大于最大X；","")&IF(AND('02_固定地理'!I5<>"",'02_固定地理'!K5<>"",'02_固定地理'!I5>'02_固定地理'!K5),"最小Y大于最大Y；","")&IF(AND('02_固定地理'!E5<>"",COUNTIF('02_固定地理'!$A$2:$A$501,'02_固定地理'!E5)=0),"父级对象不存在；","")&IF(AND('02_固定地理'!A5<>"",COUNTIF('02_固定地理'!$A$2:$A$501,'02_固定地理'!A5)>1),"ID重复；",""),"") | G5: =IF(F5<>"","按字段批注、数据字典和来源记录修正后复核","") | H5: =IF(F5<>"","待处理","")
A6: =IF(F6<>"","ISSUE-"&TEXT(ROW()-1,"00000"),"") | B6: =IF(F6<>"","错误","") | C6: =IF('02_固定地理'!A6<>"","02_固定地理","") | D6: =IF('02_固定地理'!A6<>"",'02_固定地理'!A6,"") | E6: =IF(F6<>"","综合校验","") | F6: =IF('02_固定地理'!A6<>"",IF('02_固定地理'!A6="","缺少对象ID；","")&IF('02_固定地理'!B6="","缺少中文名称；","")&IF('02_固定地理'!D6="","缺少对象类型；","")&IF(AND('02_固定地理'!F6<>"",OR('02_固定地理'!F6<0,'02_固定地理'!F6>WorldWidth)),"世界中心X越界；","")&IF(AND('02_固定地理'!G6<>"",OR('02_固定地理'!G6<0,'02_固定地理'!G6>WorldHeight)),"世界中心Y越界；","")&IF(AND('02_固定地理'!H6<>"",'02_固定地理'!J6<>"",'02_固定地理'!H6>'02_固定地理'!J6),"最小X大于最大X；","")&IF(AND('02_固定地理'!I6<>"",'02_固定地理'!K6<>"",'02_固定地理'!I6>'02_固定地理'!K6),"最小Y大于最大Y；","")&IF(AND('02_固定地理'!E6<>"",COUNTIF('02_固定地理'!$A$2:$A$501,'02_固定地理'!E6)=0),"父级对象不存在；","")&IF(AND('02_固定地理'!A6<>"",COUNTIF('02_固定地理'!$A$2:$A$501,'02_固定地理'!A6)>1),"ID重复；",""),"") | G6: =IF(F6<>"","按字段批注、数据字典和来源记录修正后复核","") | H6: =IF(F6<>"","待处理","")
A7: =IF(F7<>"","ISSUE-"&TEXT(ROW()-1,"00000"),"") | B7: =IF(F7<>"","错误","") | C7: =IF('02_固定地理'!A7<>"","02_固定地理","") | D7: =IF('02_固定地理'!A7<>"",'02_固定地理'!A7,"") | E7: =IF(F7<>"","综合校验","") | F7: =IF('02_固定地理'!A7<>"",IF('02_固定地理'!A7="","缺少对象ID；","")&IF('02_固定地理'!B7="","缺少中文名称；","")&IF('02_固定地理'!D7="","缺少对象类型；","")&IF(AND('02_固定地理'!F7<>"",OR('02_固定地理'!F7<0,'02_固定地理'!F7>WorldWidth)),"世界中心X越界；","")&IF(AND('02_固定地理'!G7<>"",OR('02_固定地理'!G7<0,'02_固定地理'!G7>WorldHeight)),"世界中心Y越界；","")&IF(AND('02_固定地理'!H7<>"",'02_固定地理'!J7<>"",'02_固定地理'!H7>'02_固定地理'!J7),"最小X大于最大X；","")&IF(AND('02_固定地理'!I7<>"",'02_固定地理'!K7<>"",'02_固定地理'!I7>'02_固定地理'!K7),"最小Y大于最大Y；","")&IF(AND('02_固定地理'!E7<>"",COUNTIF('02_固定地理'!$A$2:$A$501,'02_固定地理'!E7)=0),"父级对象不存在；","")&IF(AND('02_固定地理'!A7<>"",COUNTIF('02_固定地理'!$A$2:$A$501,'02_固定地理'!A7)>1),"ID重复；",""),"") | G7: =IF(F7<>"","按字段批注、数据字典和来源记录修正后复核","") | H7: =IF(F7<>"","待处理","")
A8: =IF(F8<>"","ISSUE-"&TEXT(ROW()-1,"00000"),"") | B8: =IF(F8<>"","错误","") | C8: =IF('02_固定地理'!A8<>"","02_固定地理","") | D8: =IF('02_固定地理'!A8<>"",'02_固定地理'!A8,"") | E8: =IF(F8<>"","综合校验","") | F8: =IF('02_固定地理'!A8<>"",IF('02_固定地理'!A8="","缺少对象ID；","")&IF('02_固定地理'!B8="","缺少中文名称；","")&IF('02_固定地理'!D8="","缺少对象类型；","")&IF(AND('02_固定地理'!F8<>"",OR('02_固定地理'!F8<0,'02_固定地理'!F8>WorldWidth)),"世界中心X越界；","")&IF(AND('02_固定地理'!G8<>"",OR('02_固定地理'!G8<0,'02_固定地理'!G8>WorldHeight)),"世界中心Y越界；","")&IF(AND('02_固定地理'!H8<>"",'02_固定地理'!J8<>"",'02_固定地理'!H8>'02_固定地理'!J8),"最小X大于最大X；","")&IF(AND('02_固定地理'!I8<>"",'02_固定地理'!K8<>"",'02_固定地理'!I8>'02_固定地理'!K8),"最小Y大于最大Y；","")&IF(AND('02_固定地理'!E8<>"",COUNTIF('02_固定地理'!$A$2:$A$501,'02_固定地理'!E8)=0),"父级对象不存在；","")&IF(AND('02_固定地理'!A8<>"",COUNTIF('02_固定地理'!$A$2:$A$501,'02_固定地理'!A8)>1),"ID重复；",""),"") | G8: =IF(F8<>"","按字段批注、数据字典和来源记录修正后复核","") | H8: =IF(F8<>"","待处理","")
A9: =IF(F9<>"","ISSUE-"&TEXT(ROW()-1,"00000"),"") | B9: =IF(F9<>"","错误","") | C9: =IF('02_固定地理'!A9<>"","02_固定地理","") | D9: =IF('02_固定地理'!A9<>"",'02_固定地理'!A9,"") | E9: =IF(F9<>"","综合校验","") | F9: =IF('02_固定地理'!A9<>"",IF('02_固定地理'!A9="","缺少对象ID；","")&IF('02_固定地理'!B9="","缺少中文名称；","")&IF('02_固定地理'!D9="","缺少对象类型；","")&IF(AND('02_固定地理'!F9<>"",OR('02_固定地理'!F9<0,'02_固定地理'!F9>WorldWidth)),"世界中心X越界；","")&IF(AND('02_固定地理'!G9<>"",OR('02_固定地理'!G9<0,'02_固定地理'!G9>WorldHeight)),"世界中心Y越界；","")&IF(AND('02_固定地理'!H9<>"",'02_固定地理'!J9<>"",'02_固定地理'!H9>'02_固定地理'!J9),"最小X大于最大X；","")&IF(AND('02_固定地理'!I9<>"",'02_固定地理'!K9<>"",'02_固定地理'!I9>'02_固定地理'!K9),"最小Y大于最大Y；","")&IF(AND('02_固定地理'!E9<>"",COUNTIF('02_固定地理'!$A$2:$A$501,'02_固定地理'!E9)=0),"父级对象不存在；","")&IF(AND('02_固定地理'!A9<>"",COUNTIF('02_固定地理'!$A$2:$A$501,'02_固定地理'!A9)>1),"ID重复；",""),"") | G9: =IF(F9<>"","按字段批注、数据字典和来源记录修正后复核","") | H9: =IF(F9<>"","待处理","")
A10: =IF(F10<>"","ISSUE-"&TEXT(ROW()-1,"00000"),"") | B10: =IF(F10<>"","错误","") | C10: =IF('02_固定地理'!A10<>"","02_固定地理","") | D10: =IF('02_固定地理'!A10<>"",'02_固定地理'!A10,"") | E10: =IF(F10<>"","综合校验","") | F10: =IF('02_固定地理'!A10<>"",IF('02_固定地理'!A10="","缺少对象ID；","")&IF('02_固定地理'!B10="","缺少中文名称；","")&IF('02_固定地理'!D10="","缺少对象类型；","")&IF(AND('02_固定地理'!F10<>"",OR('02_固定地理'!F10<0,'02_固定地理'!F10>WorldWidth)),"世界中心X越界；","")&IF(AND('02_固定地理'!G10<>"",OR('02_固定地理'!G10<0,'02_固定地理'!G10>WorldHeight)),"世界中心Y越界；","")&IF(AND('02_固定地理'!H10<>"",'02_固定地理'!J10<>"",'02_固定地理'!H10>'02_固定地理'!J10),"最小X大于最大X；","")&IF(AND('02_固定地理'!I10<>"",'02_固定地理'!K10<>"",'02_固定地理'!I10>'02_固定地理'!K10),"最小Y大于最大Y；","")&IF(AND('02_固定地理'!E10<>"",COUNTIF('02_固定地理'!$A$2:$A$501,'02_固定地理'!E10)=0),"父级对象不存在；","")&IF(AND('02_固定地理'!A10<>"",COUNTIF('02_固定地理'!$A$2:$A$501,'02_固定地理'!A10)>1),"ID重复；",""),"") | G10: =IF(F10<>"","按字段批注、数据字典和来源记录修正后复核","") | H10: =IF(F10<>"","待处理","")
A11: =IF(F11<>"","ISSUE-"&TEXT(ROW()-1,"00000"),"") | B11: =IF(F11<>"","错误","") | C11: =IF('02_固定地理'!A11<>"","02_固定地理","") | D11: =IF('02_固定地理'!A11<>"",'02_固定地理'!A11,"") | E11: =IF(F11<>"","综合校验","") | F11: =IF('02_固定地理'!A11<>"",IF('02_固定地理'!A11="","缺少对象ID；","")&IF('02_固定地理'!B11="","缺少中文名称；","")&IF('02_固定地理'!D11="","缺少对象类型；","")&IF(AND('02_固定地理'!F11<>"",OR('02_固定地理'!F11<0,'02_固定地理'!F11>WorldWidth)),"世界中心X越界；","")&IF(AND('02_固定地理'!G11<>"",OR('02_固定地理'!G11<0,'02_固定地理'!G11>WorldHeight)),"世界中心Y越界；","")&IF(AND('02_固定地理'!H11<>"",'02_固定地理'!J11<>"",'02_固定地理'!H11>'02_固定地理'!J11),"最小X大于最大X；","")&IF(AND('02_固定地理'!I11<>"",'02_固定地理'!K11<>"",'02_固定地理'!I11>'02_固定地理'!K11),"最小Y大于最大Y；","")&IF(AND('02_固定地理'!E11<>"",COUNTIF('02_固定地理'!$A$2:$A$501,'02_固定地理'!E11)=0),"父级对象不存在；","")&IF(AND('02_固定地理'!A11<>"",COUNTIF('02_固定地理'!$A$2:$A$501,'02_固定地理'!A11)>1),"ID重复；",""),"") | G11: =IF(F11<>"","按字段批注、数据字典和来源记录修正后复核","") | H11: =IF(F11<>"","待处理","")
A12: =IF(F12<>"","ISSUE-"&TEXT(ROW()-1,"00000"),"") | B12: =IF(F12<>"","错误","") | C12: =IF('02_固定地理'!A12<>"","02_固定地理","") | D12: =IF('02_固定地理'!A12<>"",'02_固定地理'!A12,"") | E12: =IF(F12<>"","综合校验","") | F12: =IF('02_固定地理'!A12<>"",IF('02_固定地理'!A12="","缺少对象ID；","")&IF('02_固定地理'!B12="","缺少中文名称；","")&IF('02_固定地理'!D12="","缺少对象类型；","")&IF(AND('02_固定地理'!F12<>"",OR('02_固定地理'!F12<0,'02_固定地理'!F12>WorldWidth)),"世界中心X越界；","")&IF(AND('02_固定地理'!G12<>"",OR('02_固定地理'!G12<0,'02_固定地理'!G12>WorldHeight)),"世界中心Y越界；","")&IF(AND('02_固定地理'!H12<>"",'02_固定地理'!J12<>"",'02_固定地理'!H12>'02_固定地理'!J12),"最小X大于最大X；","")&IF(AND('02_固定地理'!I12<>"",'02_固定地理'!K12<>"",'02_固定地理'!I12>'02_固定地理'!K12),"最小Y大于最大Y；","")&IF(AND('02_固定地理'!E12<>"",COUNTIF('02_固定地理'!$A$2:$A$501,'02_固定地理'!E12)=0),"父级对象不存在；","")&IF(AND('02_固定地理'!A12<>"",COUNTIF('02_固定地理'!$A$2:$A$501,'02_固定地理'!A12)>1),"ID重复；",""),"") | G12: =IF(F12<>"","按字段批注、数据字典和来源记录修正后复核","") | H12: =IF(F12<>"","待处理","")
A13: =IF(F13<>"","ISSUE-"&TEXT(ROW()-1,"00000"),"") | B13: =IF(F13<>"","错误","") | C13: =IF('02_固定地理'!A13<>"","02_固定地理","") | D13: =IF('02_固定地理'!A13<>"",'02_固定地理'!A13,"") | E13: =IF(F13<>"","综合校验","") | F13: =IF('02_固定地理'!A13<>"",IF('02_固定地理'!A13="","缺少对象ID；","")&IF('02_固定地理'!B13="","缺少中文名称；","")&IF('02_固定地理'!D13="","缺少对象类型；","")&IF(AND('02_固定地理'!F13<>"",OR('02_固定地理'!F13<0,'02_固定地理'!F13>WorldWidth)),"世界中心X越界；","")&IF(AND('02_固定地理'!G13<>"",OR('02_固定地理'!G13<0,'02_固定地理'!G13>WorldHeight)),"世界中心Y越界；","")&IF(AND('02_固定地理'!H13<>"",'02_固定地理'!J13<>"",'02_固定地理'!H13>'02_固定地理'!J13),"最小X大于最大X；","")&IF(AND('02_固定地理'!I13<>"",'02_固定地理'!K13<>"",'02_固定地理'!I13>'02_固定地理'!K13),"最小Y大于最大Y；","")&IF(AND('02_固定地理'!E13<>"",COUNTIF('02_固定地理'!$A$2:$A$501,'02_固定地理'!E13)=0),"父级对象不存在；","")&IF(AND('02_固定地理'!A13<>"",COUNTIF('02_固定地理'!$A$2:$A$501,'02_固定地理'!A13)>1),"ID重复；",""),"") | G13: =IF(F13<>"","按字段批注、数据字典和来源记录修正后复核","") | H13: =IF(F13<>"","待处理","")
... A501: =IF(F501<>"","ISSUE-"&TEXT(ROW()-1,"00000"),"") | B501: =IF(F501<>"","错误","") | C501: =IF('02_固定地理'!A501<>"","02_固定地理","") | D501: =IF('02_固定地理'!A501<>"",'02_固定地理'!A501,"") | E501: =IF(F501<>"","综合校验","") | F501: =IF('02_固定地理'!A501<>"",IF('02_固定地理'!A501="","缺少对象ID；","")&IF('02_固定地理'!B501="","缺少中文名称；","")&IF('02_固定地理'!D501="","缺少对象类型；","")&IF(AND('02_固定地理'!F501<>"",OR('02_固定地理'!F501<0,'02_固定地理'!F501>WorldWidth)),"世界中心X越界；","")&IF(AND('02_固定地理'!G501<>"",OR('02_固定地理'!G501<0,'02_固定地理'!G501>WorldHeight)),"世界中心Y越界；","")&IF(AND('02_固定地理'!H501<>"",'02_固定地理'!J501<>"",'02_固定地理'!H501>'02_固定地理'!J501),"最小X大于最大X；","")&IF(AND('02_固定地理'!I501<>"",'02_固定地理'!K501<>"",'02_固定地理'!I501>'02_固定地理'!K501),"最小Y大于最大Y；","")&IF(AND('02_固定地理'!E501<>"",COUNTIF('02_固定地理'!$A$2:$A$501,'02_固定地理'!E501)=0),"父级对象不存在；","")&IF(AND('02_固定地理'!A501<>"",COUNTIF('02_固定地理'!$A$2:$A$501,'02_固定地理'!A501)>1),"ID重复；",""),"") | G501: =IF(F501<>"","按字段批注、数据字典和来源记录修正后复核","") | H501: =IF(F501<>"","待处理","")
A502: =IF(F502<>"","ISSUE-"&TEXT(ROW()-1,"00000"),"") | B502: =IF(F502<>"","错误","") | C502: =IF('03_地点锚点'!A2<>"","03_地点锚点","") | D502: =IF('03_地点锚点'!A2<>"",'03_地点锚点'!A2,"") | E502: =IF(F502<>"","综合校验","") | F502: =IF('03_地点锚点'!A2<>"",IF('03_地点锚点'!A2="","缺少地点ID；","")&IF('03_地点锚点'!B2="","缺少中文名称；","")&IF('03_地点锚点'!D2="","缺少地点类型；","")&IF('03_地点锚点'!G2="","缺少世界X；","")&IF('03_地点锚点'!H2="","缺少世界Y；","")&IF(AND('03_地点锚点'!G2<>"",OR('03_地点锚点'!G2<0,'03_地点锚点'!G2>WorldWidth)),"世界X越界；","")&IF(AND('03_地点锚点'!H2<>"",OR('03_地点锚点'!H2<0,'03_地点锚点'!H2>WorldHeight)),"世界Y越界；","")&IF(AND('03_地点锚点'!E2<>"",COUNTIF('02_固定地理'!$A$2:$A$501,'03_地点锚点'!E2)=0),"父级行政对象不存在；","")&IF(AND('03_地点锚点'!F2<>"",COUNTIF('03_地点锚点'!$A$2:$A$501,'03_地点锚点'!F2)=0),"父级地点不存在；","")&IF(AND('03_地点锚点'!A2<>"",COUNTIF('03_地点锚点'!$A$2:$A$501,'03_地点锚点'!A2)>1),"ID重复；",""),"") | G502: =IF(F502<>"","按字段批注、数据字典和来源记录修正后复核","") | H502: =IF(F502<>"","待处理","")
A503: =IF(F503<>"","ISSUE-"&TEXT(ROW()-1,"00000"),"") | B503: =IF(F503<>"","错误","") | C503: =IF('03_地点锚点'!A3<>"","03_地点锚点","") | D503: =IF('03_地点锚点'!A3<>"",'03_地点锚点'!A3,"") | E503: =IF(F503<>"","综合校验","") | F503: =IF('03_地点锚点'!A3<>"",IF('03_地点锚点'!A3="","缺少地点ID；","")&IF('03_地点锚点'!B3="","缺少中文名称；","")&IF('03_地点锚点'!D3="","缺少地点类型；","")&IF('03_地点锚点'!G3="","缺少世界X；","")&IF('03_地点锚点'!H3="","缺少世界Y；","")&IF(AND('03_地点锚点'!G3<>"",OR('03_地点锚点'!G3<0,'03_地点锚点'!G3>WorldWidth)),"世界X越界；","")&IF(AND('03_地点锚点'!H3<>"",OR('03_地点锚点'!H3<0,'03_地点锚点'!H3>WorldHeight)),"世界Y越界；","")&IF(AND('03_地点锚点'!E3<>"",COUNTIF('02_固定地理'!$A$2:$A$501,'03_地点锚点'!E3)=0),"父级行政对象不存在；","")&IF(AND('03_地点锚点'!F3<>"",COUNTIF('03_地点锚点'!$A$2:$A$501,'03_地点锚点'!F3)=0),"父级地点不存在；","")&IF(AND('03_地点锚点'!A3<>"",COUNTIF('03_地点锚点'!$A$2:$A$501,'03_地点锚点'!A3)>1),"ID重复；",""),"") | G503: =IF(F503<>"","按字段批注、数据字典和来源记录修正后复核","") | H503: =IF(F503<>"","待处理","")
A504: =IF(F504<>"","ISSUE-"&TEXT(ROW()-1,"00000"),"") | B504: =IF(F504<>"","错误","") | C504: =IF('03_地点锚点'!A4<>"","03_地点锚点","") | D504: =IF('03_地点锚点'!A4<>"",'03_地点锚点'!A4,"") | E504: =IF(F504<>"","综合校验","") | F504: =IF('03_地点锚点'!A4<>"",IF('03_地点锚点'!A4="","缺少地点ID；","")&IF('03_地点锚点'!B4="","缺少中文名称；","")&IF('03_地点锚点'!D4="","缺少地点类型；","")&IF('03_地点锚点'!G4="","缺少世界X；","")&IF('03_地点锚点'!H4="","缺少世界Y；","")&IF(AND('03_地点锚点'!G4<>"",OR('03_地点锚点'!G4<0,'03_地点锚点'!G4>WorldWidth)),"世界X越界；","")&IF(AND('03_地点锚点'!H4<>"",OR('03_地点锚点'!H4<0,'03_地点锚点'!H4>WorldHeight)),"世界Y越界；","")&IF(AND('03_地点锚点'!E4<>"",COUNTIF('02_固定地理'!$A$2:$A$501,'03_地点锚点'!E4)=0),"父级行政对象不存在；","")&IF(AND('03_地点锚点'!F4<>"",COUNTIF('03_地点锚点'!$A$2:$A$501,'03_地点锚点'!F4)=0),"父级地点不存在；","")&IF(AND('03_地点锚点'!A4<>"",COUNTIF('03_地点锚点'!$A$2:$A$501,'03_地点锚点'!A4)>1),"ID重复；",""),"") | G504: =IF(F504<>"","按字段批注、数据字典和来源记录修正后复核","") | H504: =IF(F504<>"","待处理","")
A505: =IF(F505<>"","ISSUE-"&TEXT(ROW()-1,"00000"),"") | B505: =IF(F505<>"","错误","") | C505: =IF('03_地点锚点'!A5<>"","03_地点锚点","") | D505: =IF('03_地点锚点'!A5<>"",'03_地点锚点'!A5,"") | E505: =IF(F505<>"","综合校验","") | F505: =IF('03_地点锚点'!A5<>"",IF('03_地点锚点'!A5="","缺少地点ID；","")&IF('03_地点锚点'!B5="","缺少中文名称；","")&IF('03_地点锚点'!D5="","缺少地点类型；","")&IF('03_地点锚点'!G5="","缺少世界X；","")&IF('03_地点锚点'!H5="","缺少世界Y；","")&IF(AND('03_地点锚点'!G5<>"",OR('03_地点锚点'!G5<0,'03_地点锚点'!G5>WorldWidth)),"世界X越界；","")&IF(AND('03_地点锚点'!H5<>"",OR('03_地点锚点'!H5<0,'03_地点锚点'!H5>WorldHeight)),"世界Y越界；","")&IF(AND('03_地点锚点'!E5<>"",COUNTIF('02_固定地理'!$A$2:$A$501,'03_地点锚点'!E5)=0),"父级行政对象不存在；","")&IF(AND('03_地点锚点'!F5<>"",COUNTIF('03_地点锚点'!$A$2:$A$501,'03_地点锚点'!F5)=0),"父级地点不存在；","")&IF(AND('03_地点锚点'!A5<>"",COUNTIF('03_地点锚点'!$A$2:$A$501,'03_地点锚点'!A5)>1),"ID重复；",""),"") | G505: =IF(F505<>"","按字段批注、数据字典和来源记录修正后复核","") | H505: =IF(F505<>"","待处理","")
A506: =IF(F506<>"","ISSUE-"&TEXT(ROW()-1,"00000"),"") | B506: =IF(F506<>"","错误","") | C506: =IF('03_地点锚点'!A6<>"","03_地点锚点","") | D506: =IF('03_地点锚点'!A6<>"",'03_地点锚点'!A6,"") | E506: =IF(F506<>"","综合校验","") | F506: =IF('03_地点锚点'!A6<>"",IF('03_地点锚点'!A6="","缺少地点ID；","")&IF('03_地点锚点'!B6="","缺少中文名称；","")&IF('03_地点锚点'!D6="","缺少地点类型；","")&IF('03_地点锚点'!G6="","缺少世界X；","")&IF('03_地点锚点'!H6="","缺少世界Y；","")&IF(AND('03_地点锚点'!G6<>"",OR('03_地点锚点'!G6<0,'03_地点锚点'!G6>WorldWidth)),"世界X越界；","")&IF(AND('03_地点锚点'!H6<>"",OR('03_地点锚点'!H6<0,'03_地点锚点'!H6>WorldHeight)),"世界Y越界；","")&IF(AND('03_地点锚点'!E6<>"",COUNTIF('02_固定地理'!$A$2:$A$501,'03_地点锚点'!E6)=0),"父级行政对象不存在；","")&IF(AND('03_地点锚点'!F6<>"",COUNTIF('03_地点锚点'!$A$2:$A$501,'03_地点锚点'!F6)=0),"父级地点不存在；","")&IF(AND('03_地点锚点'!A6<>"",COUNTIF('03_地点锚点'!$A$2:$A$501,'03_地点锚点'!A6)>1),"ID重复；",""),"") | G506: =IF(F506<>"","按字段批注、数据字典和来源记录修正后复核","") | H506: =IF(F506<>"","待处理","")
A507: =IF(F507<>"","ISSUE-"&TEXT(ROW()-1,"00000"),"") | B507: =IF(F507<>"","错误","") | C507: =IF('03_地点锚点'!A7<>"","03_地点锚点","") | D507: =IF('03_地点锚点'!A7<>"",'03_地点锚点'!A7,"") | E507: =IF(F507<>"","综合校验","") | F507: =IF('03_地点锚点'!A7<>"",IF('03_地点锚点'!A7="","缺少地点ID；","")&IF('03_地点锚点'!B7="","缺少中文名称；","")&IF('03_地点锚点'!D7="","缺少地点类型；","")&IF('03_地点锚点'!G7="","缺少世界X；","")&IF('03_地点锚点'!H7="","缺少世界Y；","")&IF(AND('03_地点锚点'!G7<>"",OR('03_地点锚点'!G7<0,'03_地点锚点'!G7>WorldWidth)),"世界X越界；","")&IF(AND('03_地点锚点'!H7<>"",OR('03_地点锚点'!H7<0,'03_地点锚点'!H7>WorldHeight)),"世界Y越界；","")&IF(AND('03_地点锚点'!E7<>"",COUNTIF('02_固定地理'!$A$2:$A$501,'03_地点锚点'!E7)=0),"父级行政对象不存在；","")&IF(AND('03_地点锚点'!F7<>"",COUNTIF('03_地点锚点'!$A$2:$A$501,'03_地点锚点'!F7)=0),"父级地点不存在；","")&IF(AND('03_地点锚点'!A7<>"",COUNTIF('03_地点锚点'!$A$2:$A$501,'03_地点锚点'!A7)>1),"ID重复；",""),"") | G507: =IF(F507<>"","按字段批注、数据字典和来源记录修正后复核","") | H507: =IF(F507<>"","待处理","")
A508: =IF(F508<>"","ISSUE-"&TEXT(ROW()-1,"00000"),"") | B508: =IF(F508<>"","错误","") | C508: =IF('03_地点锚点'!A8<>"","03_地点锚点","") | D508: =IF('03_地点锚点'!A8<>"",'03_地点锚点'!A8,"") | E508: =IF(F508<>"","综合校验","") | F508: =IF('03_地点锚点'!A8<>"",IF('03_地点锚点'!A8="","缺少地点ID；","")&IF('03_地点锚点'!B8="","缺少中文名称；","")&IF('03_地点锚点'!D8="","缺少地点类型；","")&IF('03_地点锚点'!G8="","缺少世界X；","")&IF('03_地点锚点'!H8="","缺少世界Y；","")&IF(AND('03_地点锚点'!G8<>"",OR('03_地点锚点'!G8<0,'03_地点锚点'!G8>WorldWidth)),"世界X越界；","")&IF(AND('03_地点锚点'!H8<>"",OR('03_地点锚点'!H8<0,'03_地点锚点'!H8>WorldHeight)),"世界Y越界；","")&IF(AND('03_地点锚点'!E8<>"",COUNTIF('02_固定地理'!$A$2:$A$501,'03_地点锚点'!E8)=0),"父级行政对象不存在；","")&IF(AND('03_地点锚点'!F8<>"",COUNTIF('03_地点锚点'!$A$2:$A$501,'03_地点锚点'!F8)=0),"父级地点不存在；","")&IF(AND('03_地点锚点'!A8<>"",COUNTIF('03_地点锚点'!$A$2:$A$501,'03_地点锚点'!A8)>1),"ID重复；",""),"") | G508: =IF(F508<>"","按字段批注、数据字典和来源记录修正后复核","") | H508: =IF(F508<>"","待处理","")
A509: =IF(F509<>"","ISSUE-"&TEXT(ROW()-1,"00000"),"") | B509: =IF(F509<>"","错误","") | C509: =IF('03_地点锚点'!A9<>"","03_地点锚点","") | D509: =IF('03_地点锚点'!A9<>"",'03_地点锚点'!A9,"") | E509: =IF(F509<>"","综合校验","") | F509: =IF('03_地点锚点'!A9<>"",IF('03_地点锚点'!A9="","缺少地点ID；","")&IF('03_地点锚点'!B9="","缺少中文名称；","")&IF('03_地点锚点'!D9="","缺少地点类型；","")&IF('03_地点锚点'!G9="","缺少世界X；","")&IF('03_地点锚点'!H9="","缺少世界Y；","")&IF(AND('03_地点锚点'!G9<>"",OR('03_地点锚点'!G9<0,'03_地点锚点'!G9>WorldWidth)),"世界X越界；","")&IF(AND('03_地点锚点'!H9<>"",OR('03_地点锚点'!H9<0,'03_地点锚点'!H9>WorldHeight)),"世界Y越界；","")&IF(AND('03_地点锚点'!E9<>"",COUNTIF('02_固定地理'!$A$2:$A$501,'03_地点锚点'!E9)=0),"父级行政对象不存在；","")&IF(AND('03_地点锚点'!F9<>"",COUNTIF('03_地点锚点'!$A$2:$A$501,'03_地点锚点'!F9)=0),"父级地点不存在；","")&IF(AND('03_地点锚点'!A9<>"",COUNTIF('03_地点锚点'!$A$2:$A$501,'03_地点锚点'!A9)>1),"ID重复；",""),"") | G509: =IF(F509<>"","按字段批注、数据字典和来源记录修正后复核","") | H509: =IF(F509<>"","待处理","")
A510: =IF(F510<>"","ISSUE-"&TEXT(ROW()-1,"00000"),"") | B510: =IF(F510<>"","错误","") | C510: =IF('03_地点锚点'!A10<>"","03_地点锚点","") | D510: =IF('03_地点锚点'!A10<>"",'03_地点锚点'!A10,"") | E510: =IF(F510<>"","综合校验","") | F510: =IF('03_地点锚点'!A10<>"",IF('03_地点锚点'!A10="","缺少地点ID；","")&IF('03_地点锚点'!B10="","缺少中文名称；","")&IF('03_地点锚点'!D10="","缺少地点类型；","")&IF('03_地点锚点'!G10="","缺少世界X；","")&IF('03_地点锚点'!H10="","缺少世界Y；","")&IF(AND('03_地点锚点'!G10<>"",OR('03_地点锚点'!G10<0,'03_地点锚点'!G10>WorldWidth)),"世界X越界；","")&IF(AND('03_地点锚点'!H10<>"",OR('03_地点锚点'!H10<0,'03_地点锚点'!H10>WorldHeight)),"世界Y越界；","")&IF(AND('03_地点锚点'!E10<>"",COUNTIF('02_固定地理'!$A$2:$A$501,'03_地点锚点'!E10)=0),"父级行政对象不存在；","")&IF(AND('03_地点锚点'!F10<>"",COUNTIF('03_地点锚点'!$A$2:$A$501,'03_地点锚点'!F10)=0),"父级地点不存在；","")&IF(AND('03_地点锚点'!A10<>"",COUNTIF('03_地点锚点'!$A$2:$A$501,'03_地点锚点'!A10)>1),"ID重复；",""),"") | G510: =IF(F510<>"","按字段批注、数据字典和来源记录修正后复核","") | H510: =IF(F510<>"","待处理","")
A511: =IF(F511<>"","ISSUE-"&TEXT(ROW()-1,"00000"),"") | B511: =IF(F511<>"","错误","") | C511: =IF('03_地点锚点'!A11<>"","03_地点锚点","") | D511: =IF('03_地点锚点'!A11<>"",'03_地点锚点'!A11,"") | E511: =IF(F511<>"","综合校验","") | F511: =IF('03_地点锚点'!A11<>"",IF('03_地点锚点'!A11="","缺少地点ID；","")&IF('03_地点锚点'!B11="","缺少中文名称；","")&IF('03_地点锚点'!D11="","缺少地点类型；","")&IF('03_地点锚点'!G11="","缺少世界X；","")&IF('03_地点锚点'!H11="","缺少世界Y；","")&IF(AND('03_地点锚点'!G11<>"",OR('03_地点锚点'!G11<0,'03_地点锚点'!G11>WorldWidth)),"世界X越界；","")&IF(AND('03_地点锚点'!H11<>"",OR('03_地点锚点'!H11<0,'03_地点锚点'!H11>WorldHeight)),"世界Y越界；","")&IF(AND('03_地点锚点'!E11<>"",COUNTIF('02_固定地理'!$A$2:$A$501,'03_地点锚点'!E11)=0),"父级行政对象不存在；","")&IF(AND('03_地点锚点'!F11<>"",COUNTIF('03_地点锚点'!$A$2:$A$501,'03_地点锚点'!F11)=0),"父级地点不存在；","")&IF(AND('03_地点锚点'!A11<>"",COUNTIF('03_地点锚点'!$A$2:$A$501,'03_地点锚点'!A11)>1),"ID重复；",""),"") | G511: =IF(F511<>"","按字段批注、数据字典和来源记录修正后复核","") | H511: =IF(F511<>"","待处理","")
A512: =IF(F512<>"","ISSUE-"&TEXT(ROW()-1,"00000"),"") | B512: =IF(F512<>"","错误","") | C512: =IF('03_地点锚点'!A12<>"","03_地点锚点","") | D512: =IF('03_地点锚点'!A12<>"",'03_地点锚点'!A12,"") | E512: =IF(F512<>"","综合校验","") | F512: =IF('03_地点锚点'!A12<>"",IF('03_地点锚点'!A12="","缺少地点ID；","")&IF('03_地点锚点'!B12="","缺少中文名称；","")&IF('03_地点锚点'!D12="","缺少地点类型；","")&IF('03_地点锚点'!G12="","缺少世界X；","")&IF('03_地点锚点'!H12="","缺少世界Y；","")&IF(AND('03_地点锚点'!G12<>"",OR('03_地点锚点'!G12<0,'03_地点锚点'!G12>WorldWidth)),"世界X越界；","")&IF(AND('03_地点锚点'!H12<>"",OR('03_地点锚点'!H12<0,'03_地点锚点'!H12>WorldHeight)),"世界Y越界；","")&IF(AND('03_地点锚点'!E12<>"",COUNTIF('02_固定地理'!$A$2:$A$501,'03_地点锚点'!E12)=0),"父级行政对象不存在；","")&IF(AND('03_地点锚点'!F12<>"",COUNTIF('03_地点锚点'!$A$2:$A$501,'03_地点锚点'!F12)=0),"父级地点不存在；","")&IF(AND('03_地点锚点'!A12<>"",COUNTIF('03_地点锚点'!$A$2:$A$501,'03_地点锚点'!A12)>1),"ID重复；",""),"") | G512: =IF(F512<>"","按字段批注、数据字典和来源记录修正后复核","") | H512: =IF(F512<>"","待处理","")
A513: =IF(F513<>"","ISSUE-"&TEXT(ROW()-1,"00000"),"") | B513: =IF(F513<>"","错误","") | C513: =IF('03_地点锚点'!A13<>"","03_地点锚点","") | D513: =IF('03_地点锚点'!A13<>"",'03_地点锚点'!A13,"") | E513: =IF(F513<>"","综合校验","") | F513: =IF('03_地点锚点'!A13<>"",IF('03_地点锚点'!A13="","缺少地点ID；","")&IF('03_地点锚点'!B13="","缺少中文名称；","")&IF('03_地点锚点'!D13="","缺少地点类型；","")&IF('03_地点锚点'!G13="","缺少世界X；","")&IF('03_地点锚点'!H13="","缺少世界Y；","")&IF(AND('03_地点锚点'!G13<>"",OR('03_地点锚点'!G13<0,'03_地点锚点'!G13>WorldWidth)),"世界X越界；","")&IF(AND('03_地点锚点'!H13<>"",OR('03_地点锚点'!H13<0,'03_地点锚点'!H13>WorldHeight)),"世界Y越界；","")&IF(AND('03_地点锚点'!E13<>"",COUNTIF('02_固定地理'!$A$2:$A$501,'03_地点锚点'!E13)=0),"父级行政对象不存在；","")&IF(AND('03_地点锚点'!F13<>"",COUNTIF('03_地点锚点'!$A$2:$A$501,'03_地点锚点'!F13)=0),"父级地点不存在；","")&IF(AND('03_地点锚点'!A13<>"",COUNTIF('03_地点锚点'!$A$2:$A$501,'03_地点锚点'!A13)>1),"ID重复；",""),"") | G513: =IF(F513<>"","按字段批注、数据字典和来源记录修正后复核","") | H513: =IF(F513<>"","待处理","")
... A1001: =IF(F1001<>"","ISSUE-"&TEXT(ROW()-1,"00000"),"") | B1001: =IF(F1001<>"","错误","") | C1001: =IF('03_地点锚点'!A501<>"","03_地点锚点","") | D1001: =IF('03_地点锚点'!A501<>"",'03_地点锚点'!A501,"") | E1001: =IF(F1001<>"","综合校验","") | F1001: =IF('03_地点锚点'!A501<>"",IF('03_地点锚点'!A501="","缺少地点ID；","")&IF('03_地点锚点'!B501="","缺少中文名称；","")&IF('03_地点锚点'!D501="","缺少地点类型；","")&IF('03_地点锚点'!G501="","缺少世界X；","")&IF('03_地点锚点'!H501="","缺少世界Y；","")&IF(AND('03_地点锚点'!G501<>"",OR('03_地点锚点'!G501<0,'03_地点锚点'!G501>WorldWidth)),"世界X越界；","")&IF(AND('03_地点锚点'!H501<>"",OR('03_地点锚点'!H501<0,'03_地点锚点'!H501>WorldHeight)),"世界Y越界；","")&IF(AND('03_地点锚点'!E501<>"",COUNTIF('02_固定地理'!$A$2:$A$501,'03_地点锚点'!E501)=0),"父级行政对象不存在；","")&IF(AND('03_地点锚点'!F501<>"",COUNTIF('03_地点锚点'!$A$2:$A$501,'03_地点锚点'!F501)=0),"父级地点不存在；","")&IF(AND('03_地点锚点'!A501<>"",COUNTIF('03_地点锚点'!$A$2:$A$501,'03_地点锚点'!A501)>1),"ID重复；",""),"") | G1001: =IF(F1001<>"","按字段批注、数据字典和来源记录修正后复核","") | H1001: =IF(F1001<>"","待处理","")
A1002: =IF(F1002<>"","ISSUE-"&TEXT(ROW()-1,"00000"),"") | B1002: =IF(F1002<>"","错误","") | C1002: =IF('04_路径网络'!A2<>"","04_路径网络","") | D1002: =IF('04_路径网络'!A2<>"",'04_路径网络'!A2,"") | E1002: =IF(F1002<>"","综合校验","") | F1002: =IF('04_路径网络'!A2<>"",IF('04_路径网络'!A2="","缺少路径ID；","")&IF('04_路径网络'!C2="","缺少路径类型；","")&IF('04_路径网络'!D2="","缺少起点对象ID；","")&IF('04_路径网络'!E2="","缺少终点对象ID；","")&IF(AND('04_路径网络'!D2<>"",'04_路径网络'!D2='04_路径网络'!E2),"起点与终点相同；","")&IF(AND('04_路径网络'!D2<>"",COUNTIF('02_固定地理'!$A$2:$A$501,'04_路径网络'!D2)+COUNTIF('03_地点锚点'!$A$2:$A$501,'04_路径网络'!D2)+COUNTIF('06_建筑锚点'!$A$2:$A$501,'04_路径网络'!D2)=0),"起点引用对象不存在；","")&IF(AND('04_路径网络'!E2<>"",COUNTIF('02_固定地理'!$A$2:$A$501,'04_路径网络'!E2)+COUNTIF('03_地点锚点'!$A$2:$A$501,'04_路径网络'!E2)+COUNTIF('06_建筑锚点'!$A$2:$A$501,'04_路径网络'!E2)=0),"终点引用对象不存在；","")&IF(AND('04_路径网络'!F2<>"",COUNTIF('04_路径网络'!$A$2:$A$501,'04_路径网络'!F2)=0),"父级路径不存在；","")&IF(AND('04_路径网络'!A2<>"",COUNTIF('04_路径网络'!$A$2:$A$501,'04_路径网络'!A2)>1),"ID重复；",""),"") | G1002: =IF(F1002<>"","按字段批注、数据字典和来源记录修正后复核","") | H1002: =IF(F1002<>"","待处理","")
A1003: =IF(F1003<>"","ISSUE-"&TEXT(ROW()-1,"00000"),"") | B1003: =IF(F1003<>"","错误","") | C1003: =IF('04_路径网络'!A3<>"","04_路径网络","") | D1003: =IF('04_路径网络'!A3<>"",'04_路径网络'!A3,"") | E1003: =IF(F1003<>"","综合校验","") | F1003: =IF('04_路径网络'!A3<>"",IF('04_路径网络'!A3="","缺少路径ID；","")&IF('04_路径网络'!C3="","缺少路径类型；","")&IF('04_路径网络'!D3="","缺少起点对象ID；","")&IF('04_路径网络'!E3="","缺少终点对象ID；","")&IF(AND('04_路径网络'!D3<>"",'04_路径网络'!D3='04_路径网络'!E3),"起点与终点相同；","")&IF(AND('04_路径网络'!D3<>"",COUNTIF('02_固定地理'!$A$2:$A$501,'04_路径网络'!D3)+COUNTIF('03_地点锚点'!$A$2:$A$501,'04_路径网络'!D3)+COUNTIF('06_建筑锚点'!$A$2:$A$501,'04_路径网络'!D3)=0),"起点引用对象不存在；","")&IF(AND('04_路径网络'!E3<>"",COUNTIF('02_固定地理'!$A$2:$A$501,'04_路径网络'!E3)+COUNTIF('03_地点锚点'!$A$2:$A$501,'04_路径网络'!E3)+COUNTIF('06_建筑锚点'!$A$2:$A$501,'04_路径网络'!E3)=0),"终点引用对象不存在；","")&IF(AND('04_路径网络'!F3<>"",COUNTIF('04_路径网络'!$A$2:$A$501,'04_路径网络'!F3)=0),"父级路径不存在；","")&IF(AND('04_路径网络'!A3<>"",COUNTIF('04_路径网络'!$A$2:$A$501,'04_路径网络'!A3)>1),"ID重复；",""),"") | G1003: =IF(F1003<>"","按字段批注、数据字典和来源记录修正后复核","") | H1003: =IF(F1003<>"","待处理","")
A1004: =IF(F1004<>"","ISSUE-"&TEXT(ROW()-1,"00000"),"") | B1004: =IF(F1004<>"","错误","") | C1004: =IF('04_路径网络'!A4<>"","04_路径网络","") | D1004: =IF('04_路径网络'!A4<>"",'04_路径网络'!A4,"") | E1004: =IF(F1004<>"","综合校验","") | F1004: =IF('04_路径网络'!A4<>"",IF('04_路径网络'!A4="","缺少路径ID；","")&IF('04_路径网络'!C4="","缺少路径类型；","")&IF('04_路径网络'!D4="","缺少起点对象ID；","")&IF('04_路径网络'!E4="","缺少终点对象ID；","")&IF(AND('04_路径网络'!D4<>"",'04_路径网络'!D4='04_路径网络'!E4),"起点与终点相同；","")&IF(AND('04_路径网络'!D4<>"",COUNTIF('02_固定地理'!$A$2:$A$501,'04_路径网络'!D4)+COUNTIF('03_地点锚点'!$A$2:$A$501,'04_路径网络'!D4)+COUNTIF('06_建筑锚点'!$A$2:$A$501,'04_路径网络'!D4)=0),"起点引用对象不存在；","")&IF(AND('04_路径网络'!E4<>"",COUNTIF('02_固定地理'!$A$2:$A$501,'04_路径网络'!E4)+COUNTIF('03_地点锚点'!$A$2:$A$501,'04_路径网络'!E4)+COUNTIF('06_建筑锚点'!$A$2:$A$501,'04_路径网络'!E4)=0),"终点引用对象不存在；","")&IF(AND('04_路径网络'!F4<>"",COUNTIF('04_路径网络'!$A$2:$A$501,'04_路径网络'!F4)=0),"父级路径不存在；","")&IF(AND('04_路径网络'!A4<>"",COUNTIF('04_路径网络'!$A$2:$A$501,'04_路径网络'!A4)>1),"ID重复；",""),"") | G1004: =IF(F1004<>"","按字段批注、数据字典和来源记录修正后复核","") | H1004: =IF(F1004<>"","待处理","")
A1005: =IF(F1005<>"","ISSUE-"&TEXT(ROW()-1,"00000"),"") | B1005: =IF(F1005<>"","错误","") | C1005: =IF('04_路径网络'!A5<>"","04_路径网络","") | D1005: =IF('04_路径网络'!A5<>"",'04_路径网络'!A5,"") | E1005: =IF(F1005<>"","综合校验","") | F1005: =IF('04_路径网络'!A5<>"",IF('04_路径网络'!A5="","缺少路径ID；","")&IF('04_路径网络'!C5="","缺少路径类型；","")&IF('04_路径网络'!D5="","缺少起点对象ID；","")&IF('04_路径网络'!E5="","缺少终点对象ID；","")&IF(AND('04_路径网络'!D5<>"",'04_路径网络'!D5='04_路径网络'!E5),"起点与终点相同；","")&IF(AND('04_路径网络'!D5<>"",COUNTIF('02_固定地理'!$A$2:$A$501,'04_路径网络'!D5)+COUNTIF('03_地点锚点'!$A$2:$A$501,'04_路径网络'!D5)+COUNTIF('06_建筑锚点'!$A$2:$A$501,'04_路径网络'!D5)=0),"起点引用对象不存在；","")&IF(AND('04_路径网络'!E5<>"",COUNTIF('02_固定地理'!$A$2:$A$501,'04_路径网络'!E5)+COUNTIF('03_地点锚点'!$A$2:$A$501,'04_路径网络'!E5)+COUNTIF('06_建筑锚点'!$A$2:$A$501,'04_路径网络'!E5)=0),"终点引用对象不存在；","")&IF(AND('04_路径网络'!F5<>"",COUNTIF('04_路径网络'!$A$2:$A$501,'04_路径网络'!F5)=0),"父级路径不存在；","")&IF(AND('04_路径网络'!A5<>"",COUNTIF('04_路径网络'!$A$2:$A$501,'04_路径网络'!A5)>1),"ID重复；",""),"") | G1005: =IF(F1005<>"","按字段批注、数据字典和来源记录修正后复核","") | H1005: =IF(F1005<>"","待处理","")
A1006: =IF(F1006<>"","ISSUE-"&TEXT(ROW()-1,"00000"),"") | B1006: =IF(F1006<>"","错误","") | C1006: =IF('04_路径网络'!A6<>"","04_路径网络","") | D1006: =IF('04_路径网络'!A6<>"",'04_路径网络'!A6,"") | E1006: =IF(F1006<>"","综合校验","") | F1006: =IF('04_路径网络'!A6<>"",IF('04_路径网络'!A6="","缺少路径ID；","")&IF('04_路径网络'!C6="","缺少路径类型；","")&IF('04_路径网络'!D6="","缺少起点对象ID；","")&IF('04_路径网络'!E6="","缺少终点对象ID；","")&IF(AND('04_路径网络'!D6<>"",'04_路径网络'!D6='04_路径网络'!E6),"起点与终点相同；","")&IF(AND('04_路径网络'!D6<>"",COUNTIF('02_固定地理'!$A$2:$A$501,'04_路径网络'!D6)+COUNTIF('03_地点锚点'!$A$2:$A$501,'04_路径网络'!D6)+COUNTIF('06_建筑锚点'!$A$2:$A$501,'04_路径网络'!D6)=0),"起点引用对象不存在；","")&IF(AND('04_路径网络'!E6<>"",COUNTIF('02_固定地理'!$A$2:$A$501,'04_路径网络'!E6)+COUNTIF('03_地点锚点'!$A$2:$A$501,'04_路径网络'!E6)+COUNTIF('06_建筑锚点'!$A$2:$A$501,'04_路径网络'!E6)=0),"终点引用对象不存在；","")&IF(AND('04_路径网络'!F6<>"",COUNTIF('04_路径网络'!$A$2:$A$501,'04_路径网络'!F6)=0),"父级路径不存在；","")&IF(AND('04_路径网络'!A6<>"",COUNTIF('04_路径网络'!$A$2:$A$501,'04_路径网络'!A6)>1),"ID重复；",""),"") | G1006: =IF(F1006<>"","按字段批注、数据字典和来源记录修正后复核","") | H1006: =IF(F1006<>"","待处理","")
A1007: =IF(F1007<>"","ISSUE-"&TEXT(ROW()-1,"00000"),"") | B1007: =IF(F1007<>"","错误","") | C1007: =IF('04_路径网络'!A7<>"","04_路径网络","") | D1007: =IF('04_路径网络'!A7<>"",'04_路径网络'!A7,"") | E1007: =IF(F1007<>"","综合校验","") | F1007: =IF('04_路径网络'!A7<>"",IF('04_路径网络'!A7="","缺少路径ID；","")&IF('04_路径网络'!C7="","缺少路径类型；","")&IF('04_路径网络'!D7="","缺少起点对象ID；","")&IF('04_路径网络'!E7="","缺少终点对象ID；","")&IF(AND('04_路径网络'!D7<>"",'04_路径网络'!D7='04_路径网络'!E7),"起点与终点相同；","")&IF(AND('04_路径网络'!D7<>"",COUNTIF('02_固定地理'!$A$2:$A$501,'04_路径网络'!D7)+COUNTIF('03_地点锚点'!$A$2:$A$501,'04_路径网络'!D7)+COUNTIF('06_建筑锚点'!$A$2:$A$501,'04_路径网络'!D7)=0),"起点引用对象不存在；","")&IF(AND('04_路径网络'!E7<>"",COUNTIF('02_固定地理'!$A$2:$A$501,'04_路径网络'!E7)+COUNTIF('03_地点锚点'!$A$2:$A$501,'04_路径网络'!E7)+COUNTIF('06_建筑锚点'!$A$2:$A$501,'04_路径网络'!E7)=0),"终点引用对象不存在；","")&IF(AND('04_路径网络'!F7<>"",COUNTIF('04_路径网络'!$A$2:$A$501,'04_路径网络'!F7)=0),"父级路径不存在；","")&IF(AND('04_路径网络'!A7<>"",COUNTIF('04_路径网络'!$A$2:$A$501,'04_路径网络'!A7)>1),"ID重复；",""),"") | G1007: =IF(F1007<>"","按字段批注、数据字典和来源记录修正后复核","") | H1007: =IF(F1007<>"","待处理","")
A1008: =IF(F1008<>"","ISSUE-"&TEXT(ROW()-1,"00000"),"") | B1008: =IF(F1008<>"","错误","") | C1008: =IF('04_路径网络'!A8<>"","04_路径网络","") | D1008: =IF('04_路径网络'!A8<>"",'04_路径网络'!A8,"") | E1008: =IF(F1008<>"","综合校验","") | F1008: =IF('04_路径网络'!A8<>"",IF('04_路径网络'!A8="","缺少路径ID；","")&IF('04_路径网络'!C8="","缺少路径类型；","")&IF('04_路径网络'!D8="","缺少起点对象ID；","")&IF('04_路径网络'!E8="","缺少终点对象ID；","")&IF(AND('04_路径网络'!D8<>"",'04_路径网络'!D8='04_路径网络'!E8),"起点与终点相同；","")&IF(AND('04_路径网络'!D8<>"",COUNTIF('02_固定地理'!$A$2:$A$501,'04_路径网络'!D8)+COUNTIF('03_地点锚点'!$A$2:$A$501,'04_路径网络'!D8)+COUNTIF('06_建筑锚点'!$A$2:$A$501,'04_路径网络'!D8)=0),"起点引用对象不存在；","")&IF(AND('04_路径网络'!E8<>"",COUNTIF('02_固定地理'!$A$2:$A$501,'04_路径网络'!E8)+COUNTIF('03_地点锚点'!$A$2:$A$501,'04_路径网络'!E8)+COUNTIF('06_建筑锚点'!$A$2:$A$501,'04_路径网络'!E8)=0),"终点引用对象不存在；","")&IF(AND('04_路径网络'!F8<>"",COUNTIF('04_路径网络'!$A$2:$A$501,'04_路径网络'!F8)=0),"父级路径不存在；","")&IF(AND('04_路径网络'!A8<>"",COUNTIF('04_路径网络'!$A$2:$A$501,'04_路径网络'!A8)>1),"ID重复；",""),"") | G1008: =IF(F1008<>"","按字段批注、数据字典和来源记录修正后复核","") | H1008: =IF(F1008<>"","待处理","")
A1009: =IF(F1009<>"","ISSUE-"&TEXT(ROW()-1,"00000"),"") | B1009: =IF(F1009<>"","错误","") | C1009: =IF('04_路径网络'!A9<>"","04_路径网络","") | D1009: =IF('04_路径网络'!A9<>"",'04_路径网络'!A9,"") | E1009: =IF(F1009<>"","综合校验","") | F1009: =IF('04_路径网络'!A9<>"",IF('04_路径网络'!A9="","缺少路径ID；","")&IF('04_路径网络'!C9="","缺少路径类型；","")&IF('04_路径网络'!D9="","缺少起点对象ID；","")&IF('04_路径网络'!E9="","缺少终点对象ID；","")&IF(AND('04_路径网络'!D9<>"",'04_路径网络'!D9='04_路径网络'!E9),"起点与终点相同；","")&IF(AND('04_路径网络'!D9<>"",COUNTIF('02_固定地理'!$A$2:$A$501,'04_路径网络'!D9)+COUNTIF('03_地点锚点'!$A$2:$A$501,'04_路径网络'!D9)+COUNTIF('06_建筑锚点'!$A$2:$A$501,'04_路径网络'!D9)=0),"起点引用对象不存在；","")&IF(AND('04_路径网络'!E9<>"",COUNTIF('02_固定地理'!$A$2:$A$501,'04_路径网络'!E9)+COUNTIF('03_地点锚点'!$A$2:$A$501,'04_路径网络'!E9)+COUNTIF('06_建筑锚点'!$A$2:$A$501,'04_路径网络'!E9)=0),"终点引用对象不存在；","")&IF(AND('04_路径网络'!F9<>"",COUNTIF('04_路径网络'!$A$2:$A$501,'04_路径网络'!F9)=0),"父级路径不存在；","")&IF(AND('04_路径网络'!A9<>"",COUNTIF('04_路径网络'!$A$2:$A$501,'04_路径网络'!A9)>1),"ID重复；",""),"") | G1009: =IF(F1009<>"","按字段批注、数据字典和来源记录修正后复核","") | H1009: =IF(F1009<>"","待处理","")
A1010: =IF(F1010<>"","ISSUE-"&TEXT(ROW()-1,"00000"),"") | B1010: =IF(F1010<>"","错误","") | C1010: =IF('04_路径网络'!A10<>"","04_路径网络","") | D1010: =IF('04_路径网络'!A10<>"",'04_路径网络'!A10,"") | E1010: =IF(F1010<>"","综合校验","") | F1010: =IF('04_路径网络'!A10<>"",IF('04_路径网络'!A10="","缺少路径ID；","")&IF('04_路径网络'!C10="","缺少路径类型；","")&IF('04_路径网络'!D10="","缺少起点对象ID；","")&IF('04_路径网络'!E10="","缺少终点对象ID；","")&IF(AND('04_路径网络'!D10<>"",'04_路径网络'!D10='04_路径网络'!E10),"起点与终点相同；","")&IF(AND('04_路径网络'!D10<>"",COUNTIF('02_固定地理'!$A$2:$A$501,'04_路径网络'!D10)+COUNTIF('03_地点锚点'!$A$2:$A$501,'04_路径网络'!D10)+COUNTIF('06_建筑锚点'!$A$2:$A$501,'04_路径网络'!D10)=0),"起点引用对象不存在；","")&IF(AND('04_路径网络'!E10<>"",COUNTIF('02_固定地理'!$A$2:$A$501,'04_路径网络'!E10)+COUNTIF('03_地点锚点'!$A$2:$A$501,'04_路径网络'!E10)+COUNTIF('06_建筑锚点'!$A$2:$A$501,'04_路径网络'!E10)=0),"终点引用对象不存在；","")&IF(AND('04_路径网络'!F10<>"",COUNTIF('04_路径网络'!$A$2:$A$501,'04_路径网络'!F10)=0),"父级路径不存在；","")&IF(AND('04_路径网络'!A10<>"",COUNTIF('04_路径网络'!$A$2:$A$501,'04_路径网络'!A10)>1),"ID重复；",""),"") | G1010: =IF(F1010<>"","按字段批注、数据字典和来源记录修正后复核","") | H1010: =IF(F1010<>"","待处理","")
A1011: =IF(F1011<>"","ISSUE-"&TEXT(ROW()-1,"00000"),"") | B1011: =IF(F1011<>"","错误","") | C1011: =IF('04_路径网络'!A11<>"","04_路径网络","") | D1011: =IF('04_路径网络'!A11<>"",'04_路径网络'!A11,"") | E1011: =IF(F1011<>"","综合校验","") | F1011: =IF('04_路径网络'!A11<>"",IF('04_路径网络'!A11="","缺少路径ID；","")&IF('04_路径网络'!C11="","缺少路径类型；","")&IF('04_路径网络'!D11="","缺少起点对象ID；","")&IF('04_路径网络'!E11="","缺少终点对象ID；","")&IF(AND('04_路径网络'!D11<>"",'04_路径网络'!D11='04_路径网络'!E11),"起点与终点相同；","")&IF(AND('04_路径网络'!D11<>"",COUNTIF('02_固定地理'!$A$2:$A$501,'04_路径网络'!D11)+COUNTIF('03_地点锚点'!$A$2:$A$501,'04_路径网络'!D11)+COUNTIF('06_建筑锚点'!$A$2:$A$501,'04_路径网络'!D11)=0),"起点引用对象不存在；","")&IF(AND('04_路径网络'!E11<>"",COUNTIF('02_固定地理'!$A$2:$A$501,'04_路径网络'!E11)+COUNTIF('03_地点锚点'!$A$2:$A$501,'04_路径网络'!E11)+COUNTIF('06_建筑锚点'!$A$2:$A$501,'04_路径网络'!E11)=0),"终点引用对象不存在；","")&IF(AND('04_路径网络'!F11<>"",COUNTIF('04_路径网络'!$A$2:$A$501,'04_路径网络'!F11)=0),"父级路径不存在；","")&IF(AND('04_路径网络'!A11<>"",COUNTIF('04_路径网络'!$A$2:$A$501,'04_路径网络'!A11)>1),"ID重复；",""),"") | G1011: =IF(F1011<>"","按字段批注、数据字典和来源记录修正后复核","") | H1011: =IF(F1011<>"","待处理","")
A1012: =IF(F1012<>"","ISSUE-"&TEXT(ROW()-1,"00000"),"") | B1012: =IF(F1012<>"","错误","") | C1012: =IF('04_路径网络'!A12<>"","04_路径网络","") | D1012: =IF('04_路径网络'!A12<>"",'04_路径网络'!A12,"") | E1012: =IF(F1012<>"","综合校验","") | F1012: =IF('04_路径网络'!A12<>"",IF('04_路径网络'!A12="","缺少路径ID；","")&IF('04_路径网络'!C12="","缺少路径类型；","")&IF('04_路径网络'!D12="","缺少起点对象ID；","")&IF('04_路径网络'!E12="","缺少终点对象ID；","")&IF(AND('04_路径网络'!D12<>"",'04_路径网络'!D12='04_路径网络'!E12),"起点与终点相同；","")&IF(AND('04_路径网络'!D12<>"",COUNTIF('02_固定地理'!$A$2:$A$501,'04_路径网络'!D12)+COUNTIF('03_地点锚点'!$A$2:$A$501,'04_路径网络'!D12)+COUNTIF('06_建筑锚点'!$A$2:$A$501,'04_路径网络'!D12)=0),"起点引用对象不存在；","")&IF(AND('04_路径网络'!E12<>"",COUNTIF('02_固定地理'!$A$2:$A$501,'04_路径网络'!E12)+COUNTIF('03_地点锚点'!$A$2:$A$501,'04_路径网络'!E12)+COUNTIF('06_建筑锚点'!$A$2:$A$501,'04_路径网络'!E12)=0),"终点引用对象不存在；","")&IF(AND('04_路径网络'!F12<>"",COUNTIF('04_路径网络'!$A$2:$A$501,'04_路径网络'!F12)=0),"父级路径不存在；","")&IF(AND('04_路径网络'!A12<>"",COUNTIF('04_路径网络'!$A$2:$A$501,'04_路径网络'!A12)>1),"ID重复；",""),"") | G1012: =IF(F1012<>"","按字段批注、数据字典和来源记录修正后复核","") | H1012: =IF(F1012<>"","待处理","")
A1013: =IF(F1013<>"","ISSUE-"&TEXT(ROW()-1,"00000"),"") | B1013: =IF(F1013<>"","错误","") | C1013: =IF('04_路径网络'!A13<>"","04_路径网络","") | D1013: =IF('04_路径网络'!A13<>"",'04_路径网络'!A13,"") | E1013: =IF(F1013<>"","综合校验","") | F1013: =IF('04_路径网络'!A13<>"",IF('04_路径网络'!A13="","缺少路径ID；","")&IF('04_路径网络'!C13="","缺少路径类型；","")&IF('04_路径网络'!D13="","缺少起点对象ID；","")&IF('04_路径网络'!E13="","缺少终点对象ID；","")&IF(AND('04_路径网络'!D13<>"",'04_路径网络'!D13='04_路径网络'!E13),"起点与终点相同；","")&IF(AND('04_路径网络'!D13<>"",COUNTIF('02_固定地理'!$A$2:$A$501,'04_路径网络'!D13)+COUNTIF('03_地点锚点'!$A$2:$A$501,'04_路径网络'!D13)+COUNTIF('06_建筑锚点'!$A$2:$A$501,'04_路径网络'!D13)=0),"起点引用对象不存在；","")&IF(AND('04_路径网络'!E13<>"",COUNTIF('02_固定地理'!$A$2:$A$501,'04_路径网络'!E13)+COUNTIF('03_地点锚点'!$A$2:$A$501,'04_路径网络'!E13)+COUNTIF('06_建筑锚点'!$A$2:$A$501,'04_路径网络'!E13)=0),"终点引用对象不存在；","")&IF(AND('04_路径网络'!F13<>"",COUNTIF('04_路径网络'!$A$2:$A$501,'04_路径网络'!F13)=0),"父级路径不存在；","")&IF(AND('04_路径网络'!A13<>"",COUNTIF('04_路径网络'!$A$2:$A$501,'04_路径网络'!A13)>1),"ID重复；",""),"") | G1013: =IF(F1013<>"","按字段批注、数据字典和来源记录修正后复核","") | H1013: =IF(F1013<>"","待处理","")
... A1501: =IF(F1501<>"","ISSUE-"&TEXT(ROW()-1,"00000"),"") | B1501: =IF(F1501<>"","错误","") | C1501: =IF('04_路径网络'!A501<>"","04_路径网络","") | D1501: =IF('04_路径网络'!A501<>"",'04_路径网络'!A501,"") | E1501: =IF(F1501<>"","综合校验","") | F1501: =IF('04_路径网络'!A501<>"",IF('04_路径网络'!A501="","缺少路径ID；","")&IF('04_路径网络'!C501="","缺少路径类型；","")&IF('04_路径网络'!D501="","缺少起点对象ID；","")&IF('04_路径网络'!E501="","缺少终点对象ID；","")&IF(AND('04_路径网络'!D501<>"",'04_路径网络'!D501='04_路径网络'!E501),"起点与终点相同；","")&IF(AND('04_路径网络'!D501<>"",COUNTIF('02_固定地理'!$A$2:$A$501,'04_路径网络'!D501)+COUNTIF('03_地点锚点'!$A$2:$A$501,'04_路径网络'!D501)+COUNTIF('06_建筑锚点'!$A$2:$A$501,'04_路径网络'!D501)=0),"起点引用对象不存在；","")&IF(AND('04_路径网络'!E501<>"",COUNTIF('02_固定地理'!$A$2:$A$501,'04_路径网络'!E501)+COUNTIF('03_地点锚点'!$A$2:$A$501,'04_路径网络'!E501)+COUNTIF('06_建筑锚点'!$A$2:$A$501,'04_路径网络'!E501)=0),"终点引用对象不存在；","")&IF(AND('04_路径网络'!F501<>"",COUNTIF('04_路径网络'!$A$2:$A$501,'04_路径网络'!F501)=0),"父级路径不存在；","")&IF(AND('04_路径网络'!A501<>"",COUNTIF('04_路径网络'!$A$2:$A$501,'04_路径网络'!A501)>1),"ID重复；",""),"") | G1501: =IF(F1501<>"","按字段批注、数据字典和来源记录修正后复核","") | H1501: =IF(F1501<>"","待处理","")
...
